Errors:

###################################################################################################################

NEWLY CALCULATED
--------------------------------------------
Attribute 1: status IS TOO BIG!!!
Attribute 2: stats
id: 9117
--------------------------------------------
no of samples in pair: 128
no of samples in attribute 1: 0
no of samples in attribute 2: 128

No. of missing pairs so far:  25
Pairs previously computed so far:  109
Pairs newly computed so far:  66
  1%|▏                           | 200/28053 [2:02:37<284:36:40, 36.79s/pairs]Parsing samples with facet passages and passage IS TOO BIG!!!
Generating 7607 x 206 DataFrame...
Made it to dataframe row 500 / 7607
Made it to dataframe row 1000 / 7607
Made it to dataframe row 1500 / 7607
Made it to dataframe row 2000 / 7607
Made it to dataframe row 2500 / 7607
Made it to dataframe row 3000 / 7607
Made it to dataframe row 3500 / 7607
Made it to dataframe row 4000 / 7607
Made it to dataframe row 4500 / 7607
Made it to dataframe row 5000 / 7607
Made it to dataframe row 5500 / 7607
Made it to dataframe row 6000 / 7607
Made it to dataframe row 6500 / 7607
Made it to dataframe row 7000 / 7607
Made it to dataframe row 7500 / 7607


NEWLY CALCULATED
--------------------------------------------
Attribute 1: passages
Attribute 2: passage IS TOO BIG!!!
id: 9122
--------------------------------------------
no of samples in pair: 7607
no of samples in attribute 1: 7607
no of samples in attribute 2: 0

No. of missing pairs so far:  25
Pairs previously computed so far:  109
Pairs newly computed so far:  67
  1%|▏                           | 201/28053 [2:20:25<324:17:10, 41.92s/pairs]Parsing samples with facet treatmentDuration IS TOO BIG!!! and treatmentDescription
Generating 3027 x 105 DataFrame...
Made it to dataframe row 500 / 3027
Made it to dataframe row 1000 / 3027
Made it to dataframe row 1500 / 3027
Made it to dataframe row 2000 / 3027
Made it to dataframe row 2500 / 3027
Made it to dataframe row 3000 / 3027


NEWLY CALCULATED
--------------------------------------------
Attribute 1: treatmentDuration IS TOO BIG!!!
Attribute 2: treatmentDescription
id: 9135
--------------------------------------------
no of samples in pair: 3027
no of samples in attribute 1: 0
no of samples in attribute 2: 3027

No. of missing pairs so far:  25
Pairs previously computed so far:  109
Pairs newly computed so far:  68
Traceback (most recent call last):
  File "autocluster.py", line 597, in <module>
    tot_samples_affected = n['p'].properties['total_no_of_samples_in_pair']
KeyError: 'total_no_of_samples_in_pair'

During handling of the above exception, another exception occurred:

Traceback (most recent call last):
  File "/Users/hewgreen/anaconda3/lib/python3.6/site-packages/py2neo/packages/httpstream/http.py", line 322, in submit
    response = send()
  File "/Users/hewgreen/anaconda3/lib/python3.6/site-packages/py2neo/packages/httpstream/http.py", line 317, in send
    http.request(xstr(method), xstr(uri.absolute_path_reference), body, headers)
  File "/Users/hewgreen/anaconda3/lib/python3.6/http/client.py", line 1239, in request
    self._send_request(method, url, body, headers, encode_chunked)
  File "/Users/hewgreen/anaconda3/lib/python3.6/http/client.py", line 1285, in _send_request
    self.endheaders(body, encode_chunked=encode_chunked)
  File "/Users/hewgreen/anaconda3/lib/python3.6/http/client.py", line 1234, in endheaders
    self._send_output(message_body, encode_chunked=encode_chunked)
  File "/Users/hewgreen/anaconda3/lib/python3.6/http/client.py", line 1065, in _send_output
    self.send(chunk)
  File "/Users/hewgreen/anaconda3/lib/python3.6/http/client.py", line 986, in send
    self.sock.sendall(data)
OSError: [Errno 41] Protocol wrong type for socket

During handling of the above exception, another exception occurred:

Traceback (most recent call last):
  File "autocluster.py", line 722, in <module>
    calc_counts = run_calcs(facet1, facet2, missing_count, already_computed_count, newly_computed_count, pairID, n)
  File "autocluster.py", line 489, in run_calcs
    graph.push(n['p'])
  File "/Users/hewgreen/anaconda3/lib/python3.6/site-packages/py2neo/database/__init__.py", line 695, in push
    subgraph.__db_push__(self)
  File "/Users/hewgreen/anaconda3/lib/python3.6/site-packages/py2neo/types.py", line 484, in __db_push__
    remote(graph).resolve("batch").post(batch)
  File "/Users/hewgreen/anaconda3/lib/python3.6/site-packages/py2neo/database/http.py", line 203, in post
    response = self.__base.post(body, headers, **kwargs)
  File "/Users/hewgreen/anaconda3/lib/python3.6/site-packages/py2neo/packages/httpstream/http.py", line 984, in post
    return rq.submit(**kwargs)
  File "/Users/hewgreen/anaconda3/lib/python3.6/site-packages/py2neo/packages/httpstream/http.py", line 433, in submit
    http, rs = submit(self.method, uri, self.body, self.headers)
  File "/Users/hewgreen/anaconda3/lib/python3.6/site-packages/py2neo/packages/httpstream/http.py", line 362, in submit
    raise SocketError(code, description, host_port=uri.host_port)
py2neo.packages.httpstream.http.SocketError: Protocol wrong type for socket
hewgreen-ml:analysisTesting hewgreen$



########################################################################################################################################


NEWLY CALCULATED
--------------------------------------------
Attribute 1: collectionType
Attribute 2: collectionTime IS TOO BIG!!!
id: 8673
--------------------------------------------
no of samples in pair: 223
no of samples in attribute 1: 223
no of samples in attribute 2: 0

No. of missing pairs so far:  13
Pairs previously computed so far:  73
Pairs newly computed so far:  37
Traceback (most recent call last):
  File "autocluster.py", line 597, in <module>
    tot_samples_affected = n['p'].properties['total_no_of_samples_in_pair']
KeyError: 'total_no_of_samples_in_pair'

During handling of the above exception, another exception occurred:

Traceback (most recent call last):
  File "/Users/hewgreen/anaconda3/lib/python3.6/site-packages/py2neo/packages/httpstream/http.py", line 322, in submit
    response = send()
  File "/Users/hewgreen/anaconda3/lib/python3.6/site-packages/py2neo/packages/httpstream/http.py", line 317, in send
    http.request(xstr(method), xstr(uri.absolute_path_reference), body, headers)
  File "/Users/hewgreen/anaconda3/lib/python3.6/http/client.py", line 1239, in request
    self._send_request(method, url, body, headers, encode_chunked)
  File "/Users/hewgreen/anaconda3/lib/python3.6/http/client.py", line 1285, in _send_request
    self.endheaders(body, encode_chunked=encode_chunked)
  File "/Users/hewgreen/anaconda3/lib/python3.6/http/client.py", line 1234, in endheaders
    self._send_output(message_body, encode_chunked=encode_chunked)
  File "/Users/hewgreen/anaconda3/lib/python3.6/http/client.py", line 1065, in _send_output
    self.send(chunk)
  File "/Users/hewgreen/anaconda3/lib/python3.6/http/client.py", line 986, in send
    self.sock.sendall(data)
OSError: [Errno 41] Protocol wrong type for socket

During handling of the above exception, another exception occurred:

Traceback (most recent call last):
  File "autocluster.py", line 722, in <module>
    calc_counts = run_calcs(facet1, facet2, missing_count, already_computed_count, newly_computed_count, pairID, n)
  File "autocluster.py", line 489, in run_calcs
    graph.push(n['p'])
  File "/Users/hewgreen/anaconda3/lib/python3.6/site-packages/py2neo/database/__init__.py", line 695, in push
    subgraph.__db_push__(self)
  File "/Users/hewgreen/anaconda3/lib/python3.6/site-packages/py2neo/types.py", line 484, in __db_push__
    remote(graph).resolve("batch").post(batch)
  File "/Users/hewgreen/anaconda3/lib/python3.6/site-packages/py2neo/database/http.py", line 203, in post
    response = self.__base.post(body, headers, **kwargs)
  File "/Users/hewgreen/anaconda3/lib/python3.6/site-packages/py2neo/packages/httpstream/http.py", line 984, in post
    return rq.submit(**kwargs)
  File "/Users/hewgreen/anaconda3/lib/python3.6/site-packages/py2neo/packages/httpstream/http.py", line 433, in submit
    http, rs = submit(self.method, uri, self.body, self.headers)
  File "/Users/hewgreen/anaconda3/lib/python3.6/site-packages/py2neo/packages/httpstream/http.py", line 362, in submit
    raise SocketError(code, description, host_port=uri.host_port)
py2neo.packages.httpstream.http.SocketError: Protocol wrong type for socket



########################################################################################################################################



/Users/hewgreen/anaconda3/lib/python3.6/site-packages/scipy/cluster/hierarchy.py:1173: RuntimeWarning:

invalid value encountered in double_scalars

/Users/hewgreen/anaconda3/lib/python3.6/site-packages/matplotlib/axes/_base.py:3193: UserWarning:

Attempting to set identical bottom==top results
in singular transformations; automatically expanding.
bottom=0, top=0.0


